Workbook

Sheet Stok Fisik
A1: Kode Produk | B1: Kategori | C1: Nama Barang | D1: Merk | E1: Jenis | F1: Status | G1: Stok | H1: Harga Modal | I1: Harga Jual | J1: Margin | K1: Margin (%)
A2: RJA-3-0001 | B2: AKSESORIS | C2: vivan VSPT04T PRO | D2: VIVAN | E2: TEMPERED GLASS | F2: =IF(G2="", "", IF(G2<=0, "Habis", IF(G2<=3, "Menipis", "Tersedia"))) -> Tersedia | G2: 5 | H2: 45000 | I2: 60000 | J2: =I2-H2 -> 15000 | K2: =J2/H2*100% -> 0.33333333
A3: RJA-ACOM-0001 | B3: AKSESORIS | C3: ACOME Microphone AWA-V7B Black | D3: ACOME | E3: BROADCAST | F3: =IF(G3="", "", IF(G3<=0, "Habis", IF(G3<=3, "Menipis", "Tersedia"))) -> Menipis | G3: 2 | H3: 145000 | I3: 220000 | J3: =I3-H3 -> 75000 | K3: =J3/H3*100% -> 0.51724138
A4: RJA-ACOM-0002 | B4: AKSESORIS | C4: ACOME ACC Mini Fan AF002 Dark Blue | D4: ACOME | E4: KIPAS | F4: =IF(G4="", "", IF(G4<=0, "Habis", IF(G4<=3, "Menipis", "Tersedia"))) -> Menipis | G4: 1 | H4: 87898 | I4: 170000 | J4: =I4-H4 -> 82102 | K4: =J4/H4*100% -> 0.93405993
A5: RJA-ACOM-0003 | B5: AKSESORIS | C5: ACOME TF CARD 32G TF WITH Package colourful | D5: ACOME | E5: MMC | F5: =IF(G5="", "", IF(G5<=0, "Habis", IF(G5<=3, "Menipis", "Tersedia"))) -> Menipis | G5: 1 | H5: 41766 | I5: 75179 | J5: =I5-H5 -> 33413 | K5: =J5/H5*100% -> 0.80000479
A6: RJA-ACOM-0004 | B6: AKSESORIS | C6: ACOME selfie stick SS07A black (SKU RJA-ACOM-0890) | D6: ACOME | E6: TRIPOD | F6: =IF(G6="", "", IF(G6<=0, "Habis", IF(G6<=3, "Menipis", "Tersedia"))) -> Menipis | G6: 2 | H6: 40000 | I6: 80000 | J6: =I6-H6 -> 40000 | K6: =J6/H6*100% -> 1
A7: RJA-ACOM-0005 | B7: AKSESORIS | C7: ACOME selfie stick SS07A black (SKU RJA-ACOM-0903) | D7: ACOME | E7: TRIPOD | F7: =IF(G7="", "", IF(G7<=0, "Habis", IF(G7<=3, "Menipis", "Tersedia"))) -> Menipis | G7: 1 | H7: 38899 | I7: 70018 | J7: =I7-H7 -> 31119 | K7: =J7/H7*100% -> 0.79999486
A8: RJA-ACOM-0006 | B8: AKSESORIS | C8: ACOME ACC Ows Earphone A21 Black (SKU RJA-ACOM-0927) | D8: ACOME | E8: TWS | F8: =IF(G8="", "", IF(G8<=0, "Habis", IF(G8<=3, "Menipis", "Tersedia"))) -> Menipis | G8: 2 | H8: 170000 | I8: 260000 | J8: =I8-H8 -> 90000 | K8: =J8/H8*100% -> 0.52941176
A9: RJA-ACOM-0007 | B9: AKSESORIS | C9: ACOME Tws Earphone Inpods AT03 Black (SKU RJA-ACOM-0928) | D9: ACOME | E9: TWS | F9: =IF(G9="", "", IF(G9<=0, "Habis", IF(G9<=3, "Menipis", "Tersedia"))) -> Menipis | G9: 1 | H9: 140530 | I9: 200000 | J9: =I9-H9 -> 59470 | K9: =J9/H9*100% -> 0.42318366
A10: RJA-ACOM-0008 | B10: AKSESORIS | C10: ACOME TWS Inpods AT09 Black (SKU RJA-ACOM-0931) | D10: ACOME | E10: TWS | F10: =IF(G10="", "", IF(G10<=0, "Habis", IF(G10<=3, "Menipis", "Tersedia"))) -> Menipis | G10: 1 | H10: 125000 | I10: 185000 | J10: =I10-H10 -> 60000 | K10: =J10/H10*100% -> 0.48
A11: RJA-ACOM-0009 | B11: AKSESORIS | C11: ACOME Tws Earphone Inpods AT03 Black (SKU RJA-ACOM-0932) | D11: ACOME | E11: TWS | F11: =IF(G11="", "", IF(G11<=0, "Habis", IF(G11<=3, "Menipis", "Tersedia"))) -> Menipis | G11: 1 | H11: 145000 | I11: 200000 | J11: =I11-H11 -> 55000 | K11: =J11/H11*100% -> 0.37931034
A12: RJA-ACOM-0010 | B12: AKSESORIS | C12: ACOME TWS Inpods AT09 Black (SKU RJA-ACOM-0941) | D12: ACOME | E12: TWS | F12: =IF(G12="", "", IF(G12<=0, "Habis", IF(G12<=3, "Menipis", "Tersedia"))) -> Menipis | G12: 1 | H12: 117000 | I12: 163800 | J12: =I12-H12 -> 46800 | K12: =J12/H12*100% -> 0.4
A13: RJA-ACOM-0011 | B13: AKSESORIS | C13: ACOME Tws Earphone Inpods AT03 Green | D13: ACOME | E13: TWS | F13: =IF(G13="", "", IF(G13<=0, "Habis", IF(G13<=3, "Menipis", "Tersedia"))) -> Menipis | G13: 1 | H13: 119365 | I13: 200000 | J13: =I13-H13 -> 80635 | K13: =J13/H13*100% -> 0.67553303
... A16: RJA-ADAP-0001 | B16: AKSESORIS | C16: ADAPTER 7IN1 TYPE C+ USB A GREY | D16: WELCOME | E16: ADAPTER | F16: =IF(G16="", "", IF(G16<=0, "Habis", IF(G16<=3, "Menipis", "Tersedia"))) -> Menipis | G16: 1 | H16: 67375 | I16: 110000 | J16: =I16-H16 -> 42625 | K16: =J16/H16*100% -> 0.63265306
A17: RJA-AKS-0001 | B17: AKSESORIS | C17: MOUSEPAD GAMER | D17: NO BRAND | E17: MOUSEPAD | F17: =IF(G17="", "", IF(G17<=0, "Habis", IF(G17<=3, "Menipis", "Tersedia"))) -> Menipis | G17: 1 | H17: 13500 | I17: 35000 | J17: 22500 | K17: 1.8
A18: RJA-ANTE-0001 | B18: AKSESORIS | C18: ANTENA AUX | D18: NO BRAND | E18: AUX | F18: =IF(G18="", "", IF(G18<=0, "Habis", IF(G18<=3, "Menipis", "Tersedia"))) -> Menipis | G18: 1 | H18: 10000 | I18: 20000 | J18: =I18-H18 -> 10000 | K18: =J18/H18*100% -> 1
A19: RJA-ARCB-0001 | B19: AKSESORIS | C19: ARC BBQ LIGHTER | D19: NO BRAND | E19: Aksesoris Lainnya | F19: =IF(G19="", "", IF(G19<=0, "Habis", IF(G19<=3, "Menipis", "Tersedia"))) -> Menipis | G19: 1 | H19: 12500 | I19: 25000 | J19: =I19-H19 -> 12500 | K19: =J19/H19*100% -> 1
A20: RJA-AUX2-0001 | B20: AKSESORIS | C20: AUX 2 IN 1 1,5 M | D20: NO BRAND | E20: AUX | F20: =IF(G20="", "", IF(G20<=0, "Habis", IF(G20<=3, "Menipis", "Tersedia"))) -> Menipis | G20: 3 | H20: 7000 | I20: 20000 | J20: =I20-H20 -> 13000 | K20: =J20/H20*100% -> 1.8571429
A21: RJA-AUX2-0002 | B21: AKSESORIS | C21: AUX 2 IN 1 1 M | D21: NO BRAND | E21: AUX | F21: =IF(G21="", "", IF(G21<=0, "Habis", IF(G21<=3, "Menipis", "Tersedia"))) -> Menipis | G21: 3 | H21: 6000 | I21: 15000 | J21: =I21-H21 -> 9000 | K21: =J21/H21*100% -> 1.5
A22: RJA-AUXA-0001 | B22: AKSESORIS | C22: AUX ACCESORIES | D22: NO BRAND | E22: AUX | F22: =IF(G22="", "", IF(G22<=0, "Habis", IF(G22<=3, "Menipis", "Tersedia"))) -> Tersedia | G22: 8 | H22: 6000 | I22: 25000 | J22: =I22-H22 -> 19000 | K22: =J22/H22*100% -> 3.1666667
A23: RJA-AUXA-0002 | B23: AKSESORIS | C23: AUX AV-005 1,5 | D23: NO BRAND | E23: AUX | F23: =IF(G23="", "", IF(G23<=0, "Habis", IF(G23<=3, "Menipis", "Tersedia"))) -> Tersedia | G23: 4 | H23: 7000 | I23: 20000 | J23: =I23-H23 -> 13000 | K23: =J23/H23*100% -> 1.8571429
A24: RJA-AUXA-0003 | B24: AKSESORIS | C24: AUX ALIEN | D24: ALIENS | E24: AUX | F24: =IF(G24="", "", IF(G24<=0, "Habis", IF(G24<=3, "Menipis", "Tersedia"))) -> Tersedia | G24: 5 | H24: 7500 | I24: 20000 | J24: =I24-H24 -> 12500 | K24: =J24/H24*100% -> 1.6666667
A25: RJA-AUXA-0004 | B25: AKSESORIS | C25: AUX AV-003 (SKU RJA-AUXA-0066) | D25: NO BRAND | E25: AUX AV-003 1,5 M | F25: =IF(G25="", "", IF(G25<=0, "Habis", IF(G25<=3, "Menipis", "Tersedia"))) -> Menipis | G25: 2 | H25: 5000 | I25: 15000 | J25: =I25-H25 -> 10000 | K25: =J25/H25*100% -> 2
A26: RJA-AUXA-0005 | B26: AKSESORIS | C26: AUX AV-003 (SKU RJA-AUXA-0067) | D26: NO BRAND | E26: AUX AV-003 1,5 M | F26: =IF(G26="", "", IF(G26<=0, "Habis", IF(G26<=3, "Menipis", "Tersedia"))) -> Menipis | G26: 2 | H26: 5000 | I26: 15000 | J26: =I26-H26 -> 10000 | K26: =J26/H26*100% -> 2
A27: RJA-AUXD-0001 | B27: AKSESORIS | C27: AUX DAP D-AU07 | D27: DAP | E27: AUX | F27: =IF(G27="", "", IF(G27<=0, "Habis", IF(G27<=3, "Menipis", "Tersedia"))) -> Menipis | G27: 1 | H27: 20000 | I27: 35000 | J27: =I27-H27 -> 15000 | K27: =J27/H27*100% -> 0.75
A28: RJA-AUXD-0002 | B28: AKSESORIS | C28: AUX DAP D-AU08 | D28: DAP | E28: AUX | F28: =IF(G28="", "", IF(G28<=0, "Habis", IF(G28<=3, "Menipis", "Tersedia"))) -> Menipis | G28: 1 | H28: 24000 | I28: 40000 | J28: =I28-H28 -> 16000 | K28: =J28/H28*100% -> 0.66666667
A29: RJA-AUXD-0003 | B29: AKSESORIS | C29: AUX DAP D-AU09 | D29: DAP | E29: AUX | F29: =IF(G29="", "", IF(G29<=0, "Habis", IF(G29<=3, "Menipis", "Tersedia"))) -> Menipis | G29: 2 | H29: 21500 | I29: 35000 | J29: =I29-H29 -> 13500 | K29: =J29/H29*100% -> 0.62790698
... A51: RJA-BLUE-0001 | B51: AKSESORIS | C51: BLUETOOTH BANDO MAX PRO2 | D51: NO BRAND | E51: BANDO | F51: =IF(G51="", "", IF(G51<=0, "Habis", IF(G51<=3, "Menipis", "Tersedia"))) -> Menipis | G51: 1 | H51: 75000 | I51: 150000 | J51: =I51-H51 -> 75000 | K51: =J51/H51*100% -> 1
A52: RJA-BLUE-0005 | B52: Aksesoris | C52: BLUETOOTH RECEIVER LENYES LR- 208 ( ADA MIC ) | D52: LENYES | E52: REECIEVER | F52: Menipis | G52: 2 | H52: 43500 | I52: 90000 | J52: 46500 | K52: 1.07
A53: RJA-BREK-0001 | B53: AKSESORIS | C53: BREKET MOTOR STANG | D53: NO BRAND | E53: HOLDER | F53: =IF(G53="", "", IF(G53<=0, "Habis", IF(G53<=3, "Menipis", "Tersedia"))) -> Menipis | G53: 3 | H53: 9500 | I53: 25000 | J53: =I53-H53 -> 15500 | K53: =J53/H53*100% -> 1.6315789
A54: RJA-CALC-0001 | B54: Aksesoris | C54: CALCULATOR AIMILO | D54: AIMILO | E54: AKSESORIS LAIN | F54: Menipis | G54: 2 | H54: 13500 | I54: 30000 | J54: 16500 | K54: 1.22
A55: RJA-CANO-0001 | B55: Aksesoris | C55: CAN OPENER | D55: No Brand | E55: AKSESORIS LAIN | F55: Menipis | G55: 1 | H55: 13500 | I55: 20000 | J55: 6500 | K55: 0.48
A56: RJA-CARC-0001 | B56: AKSESORIS | C56: Car Charger Iphone USB-C 20W | D56: IPHONE | E56: CAR CHARGER | F56: =IF(G56="", "", IF(G56<=0, "Habis", IF(G56<=3, "Menipis", "Tersedia"))) -> Menipis | G56: 2 | H56: 30000 | I56: 60000 | J56: =I56-H56 -> 30000 | K56: =J56/H56*100% -> 1
A57: RJA-CARC-0002 | B57: AKSESORIS | C57: CAR CHARGER DAP D-CCP2 | D57: DAP | E57: CAR CHARGER | F57: =IF(G57="", "", IF(G57<=0, "Habis", IF(G57<=3, "Menipis", "Tersedia"))) -> Menipis | G57: 1 | H57: 58750 | I57: 95000 | J57: =I57-H57 -> 36250 | K57: =J57/H57*100% -> 0.61702128
A58: RJA-CARC-0003 | B58: AKSESORIS | C58: CAR CHARGER DAP D-CC10M | D58: DAP | E58: CAR CHARGER | F58: =IF(G58="", "", IF(G58<=0, "Habis", IF(G58<=3, "Menipis", "Tersedia"))) -> Menipis | G58: 1 | H58: 61500 | I58: 100000 | J58: =I58-H58 -> 38500 | K58: =J58/H58*100% -> 0.62601626
A59: RJA-CARC-0004 | B59: AKSESORIS | C59: CAR CHARGER DAP D-CC45 | D59: DAP | E59: CAR CHARGER | F59: =IF(G59="", "", IF(G59<=0, "Habis", IF(G59<=3, "Menipis", "Tersedia"))) -> Menipis | G59: 1 | H59: 61000 | I59: 110000 | J59: =I59-H59 -> 49000 | K59: =J59/H59*100% -> 0.80327869
A60: RJA-CARC-0005 | B60: AKSESORIS | C60: CAR CHARGER R20 BLACK | D60: NO BRAND | E60: CAR CHARGER | F60: =IF(G60="", "", IF(G60<=0, "Habis", IF(G60<=3, "Menipis", "Tersedia"))) -> Tersedia | G60: 5 | H60: 46250 | I60: 70000 | J60: =I60-H60 -> 23750 | K60: =J60/H60*100% -> 0.51351351
A61: RJA-CARC-0006 | B61: AKSESORIS | C61: CAR CHARGER SM-03 | D61: NO BRAND | E61: CAR CHARGER | F61: =IF(G61="", "", IF(G61<=0, "Habis", IF(G61<=3, "Menipis", "Tersedia"))) -> Menipis | G61: 1 | H61: 7500 | I61: 20000 | J61: =I61-H61 -> 12500 | K61: =J61/H61*100% -> 1.6666667
A62: RJA-CARC-0007 | B62: AKSESORIS | C62: CAR CHARGER 6A QUALCOMM 3.0 | D62: NO BRAND | E62: CAR CHARGER | F62: =IF(G62="", "", IF(G62<=0, "Habis", IF(G62<=3, "Menipis", "Tersedia"))) -> Tersedia | G62: 19 | H62: 14000 | I62: 30000 | J62: =I62-H62 -> 16000 | K62: =J62/H62*100% -> 1.1428571
A63: RJA-CARC-0008 | B63: AKSESORIS | C63: CAR CHARGER DAP 2 USB D-CC1 | D63: DAP | E63: CAR CHARGER | F63: =IF(G63="", "", IF(G63<=0, "Habis", IF(G63<=3, "Menipis", "Tersedia"))) -> Habis | G63: 0 | H63: 15000 | I63: 30000 | J63: =I63-H63 -> 15000 | K63: =J63/H63*100% -> 1
...

Sheet Stok Digital
A1: Kode Produk | B1: Kategori | C1: Nama Layanan | D1: Merk | E1: Jenis | F1: Status | G1: Harga Modal | H1: Harga Jual | I1: Margin | J1: Margin (%)
A2: RJA-XL-0001 | B2: Pulsa | C2: XL COMBO FLEX MAX - 7 GB 28 HARI | D2: Xl | E2: MULTI | F2: Aktif | G2: 32174 | H2: 35000 | I2: {=IF(A2:A1997="", "", H2:H1997 - G2:G1997)} -> 2826 | J2: {=IF(A2:A1997="", "", IFERROR(I2:I1997 / G2:G1997, 0))} -> 0.087834898
A3: RJA-XL-0002 | B3: Pulsa | C3: XL COMBO FLEX MAX - 10 GB 28 HARI | D3: Xl | E3: MULTI | F3: Aktif | G3: 37110 | H3: 40000 | I3: 2890 | J3: 0.077876583
A4: RJA-XL-0003 | B4: Pulsa | C4: XL COMBO FLEX MAX - 16 GB 28 HARI | D4: Xl | E4: MULTI | F4: Aktif | G4: 45550 | H4: 49000 | I4: 3450 | J4: 0.075740944
A5: RJA-XL-0004 | B5: Pulsa | C5: XL COMBO FLEX MAX - 23 GB 28 HARI | D5: Xl | E5: MULTI | F5: Aktif | G5: 54548 | H5: 59000 | I5: 4452 | J5: 0.081616191
A6: RJA-XL-0005 | B6: Pulsa | C6: XL COMBO FLEX MAX - 33 GB 14 HARI | D6: Xl | E6: MULTI | F6: Aktif | G6: 66205 | H6: 70000 | I6: 3795 | J6: 0.057321955
A7: RJA-XL-0006 | B7: Pulsa | C7: XL COMBO FLEX MAX - 31 GB 28 HARI | D7: Xl | E7: MULTI | F7: Aktif | G7: 62669 | H7: 66000 | I7: 3331 | J7: 0.053152276
A8: RJA-XL-0007 | B8: Pulsa | C8: XL COMBO FLEX MAX - 75 GB 15 HARI | D8: Xl | E8: MULTI | F8: Aktif | G8: 68365 | H8: 74000 | I8: 5635 | J8: 0.082425218
A9: RJA-XL-0008 | B9: Pulsa | C9: XL COMBO FLEX MAX - 40 GB 28 HARI | D9: Xl | E9: MULTI | F9: Aktif | G9: 70046 | H9: 75000 | I9: 4954 | J9: 0.070724952
A10: RJA-XL-0009 | B10: Pulsa | C10: XL COMBO FLEX MAX - 50 GB 28 HARI | D10: Xl | E10: MULTI | F10: Aktif | G10: 78925 | H10: 85000 | I10: 6075 | J10: 0.076971809
A11: RJA-XL-0010 | B11: Pulsa | C11: XL COMBO FLEX MAX - 65 GB 28 HARI | D11: Xl | E11: MULTI | F11: Aktif | G11: 89290 | H11: 95000 | I11: 5710 | J11: 0.06394893
A12: RJA-XL-0011 | B12: Pulsa | C12: XL COMBO FLEX MAX - 100 GB 28 HARI | D12: Xl | E12: MULTI | F12: Aktif | G12: 115200 | H12: 120000 | I12: 4800 | J12: 0.041666667
A13: RJA-XL-0012 | B13: Pulsa | C13: XL HARIAN - HARIAN S (2 GB - 3 GB) 3 HARI | D13: Xl | E13: MULTI | F13: Aktif | G13: 11678 | H13: 14000 | I13: 2322 | J13: 0.19883542
A14: RJA-XL-0013 | B14: Pulsa | C14: XL HARIAN - HARIAN S (2 GB - 3.5 GB) 5 HARI | D14: Xl | E14: MULTI | F14: Aktif | G14: 13700 | H14: 16000 | I14: 2300 | J14: 0.16788321
... A1027: RJA-DANA-0008 | B1027: TRANSFER | C1027: DANA TOP UP DANA - TOP UP DANA 20001K - 3000K | D1027: Dana | E1027: DANA | F1027: Aktif | G1027: 0 | H1027: 20000 | I1027: 20000 | J1027: 0
G1028: 0 | H1028: 0
G1029: 0 | H1029: 0
G1030: 0 | H1030: 0
G1031: 0 | H1031: 0
G1032: 0 | H1032: 0
G1033: 0 | H1033: 0
G1034: 0 | H1034: 0
G1035: 0 | H1035: 0
G1036: 0 | H1036: 0
G1037: 0 | H1037: 0
G1038: 0 | H1038: 0
G1039: 0 | H1039: 0
... G1997: 0 | H1997: 0

Sheet Input Produk Baru
D1: Form Input Produk
D3: Jenis Stok | E3: Fisik | G3: Harga Modal | H3: 16000
D4: Nama Barang/Layanan | G4: Harga Jual | H4: 35000
D5: Kategori
D6: Jenis
D7: Merk
D8: Kode Produk | E8: RJA-AKS-0001
D9: Stok | E9: 2

Sheet Input Saldo
D1: Form Input Saldo
D3: Tanggal
D4: Nama Transaksi
D5: Akun Tujuan
D6: Akun Asal
D8: Tipe Transaksi
D9: Nominal Saldo

Sheet Saldo
D2: MONITORING SALDO AKTUAL
D4: Akun Saldo | E4: Saldo Masuk | F4: Saldo Keluar | G4: Saldo Aktual
D5: MULTI | E5: =IFS($D$12="Hari Ini", SUMIFS('Saldo (Transaksi)'!F:F, 'Saldo (Transaksi)'!D:D, $D5, 'Saldo (Transaksi)'!A:A, TODAY()), $D$12="Bulan Ini", SUMIFS('Saldo (Transaksi)'!F:F, 'Saldo (Transaksi)'!D:D, $D5, 'Saldo (Transaksi)'!A:A, ">="&EOMONTH(TODAY(), -1)+1, 'Saldo (Transaksi)'!A:A, "<="&EOMONTH(TODAY(), 0)), $D$12="Pilih Tanggal", SUMIFS('Saldo (Transaksi)'!F:F, 'Saldo (Transaksi)'!D:D, $D5, 'Saldo (Transaksi)'!A:A, $F$12), TRUE, SUMIFS('Saldo (Transaksi)'!F:F, 'Saldo (Transaksi)'!D:D, $D5)) -> 0 | F5: =IFS($D$12="Hari Ini", SUMIFS('Saldo (Transaksi)'!F:F, 'Saldo (Transaksi)'!E:E, $D5, 'Saldo (Transaksi)'!A:A, TODAY()), $D$12="Bulan Ini", SUMIFS('Saldo (Transaksi)'!F:F, 'Saldo (Transaksi)'!E:E, $D5, 'Saldo (Transaksi)'!A:A, ">="&EOMONTH(TODAY(), -1)+1, 'Saldo (Transaksi)'!A:A, "<="&EOMONTH(TODAY(), 0)), $D$12="Pilih Tanggal", SUMIFS('Saldo (Transaksi)'!F:F, 'Saldo (Transaksi)'!E:E, $D5, 'Saldo (Transaksi)'!A:A, $F$12), TRUE, SUMIFS('Saldo (Transaksi)'!F:F, 'Saldo (Transaksi)'!E:E, $D5)) -> 0 | G5: =SUMIFS('Saldo (Transaksi)'!F:F, 'Saldo (Transaksi)'!D:D, $D5) - SUMIFS('Saldo (Transaksi)'!F:F, 'Saldo (Transaksi)'!E:E, $D5) -> 0
D6: DANA | E6: =IFS($D$12="Hari Ini", SUMIFS('Saldo (Transaksi)'!F:F, 'Saldo (Transaksi)'!D:D, $D6, 'Saldo (Transaksi)'!A:A, TODAY()), $D$12="Bulan Ini", SUMIFS('Saldo (Transaksi)'!F:F, 'Saldo (Transaksi)'!D:D, $D6, 'Saldo (Transaksi)'!A:A, ">="&EOMONTH(TODAY(), -1)+1, 'Saldo (Transaksi)'!A:A, "<="&EOMONTH(TODAY(), 0)), $D$12="Pilih Tanggal", SUMIFS('Saldo (Transaksi)'!F:F, 'Saldo (Transaksi)'!D:D, $D6, 'Saldo (Transaksi)'!A:A, $F$12), TRUE, SUMIFS('Saldo (Transaksi)'!F:F, 'Saldo (Transaksi)'!D:D, $D6)) -> 0 | F6: =IFS($D$12="Hari Ini", SUMIFS('Saldo (Transaksi)'!F:F, 'Saldo (Transaksi)'!E:E, $D6, 'Saldo (Transaksi)'!A:A, TODAY()), $D$12="Bulan Ini", SUMIFS('Saldo (Transaksi)'!F:F, 'Saldo (Transaksi)'!E:E, $D6, 'Saldo (Transaksi)'!A:A, ">="&EOMONTH(TODAY(), -1)+1, 'Saldo (Transaksi)'!A:A, "<="&EOMONTH(TODAY(), 0)), $D$12="Pilih Tanggal", SUMIFS('Saldo (Transaksi)'!F:F, 'Saldo (Transaksi)'!E:E, $D6, 'Saldo (Transaksi)'!A:A, $F$12), TRUE, SUMIFS('Saldo (Transaksi)'!F:F, 'Saldo (Transaksi)'!E:E, $D6)) -> 0 | G6: =SUMIFS('Saldo (Transaksi)'!F:F, 'Saldo (Transaksi)'!D:D, $D6) - SUMIFS('Saldo (Transaksi)'!F:F, 'Saldo (Transaksi)'!E:E, $D6) -> 0
D7: BANK MAS | E7: =IFS($D$12="Hari Ini", SUMIFS('Saldo (Transaksi)'!F:F, 'Saldo (Transaksi)'!D:D, $D7, 'Saldo (Transaksi)'!A:A, TODAY()), $D$12="Bulan Ini", SUMIFS('Saldo (Transaksi)'!F:F, 'Saldo (Transaksi)'!D:D, $D7, 'Saldo (Transaksi)'!A:A, ">="&EOMONTH(TODAY(), -1)+1, 'Saldo (Transaksi)'!A:A, "<="&EOMONTH(TODAY(), 0)), $D$12="Pilih Tanggal", SUMIFS('Saldo (Transaksi)'!F:F, 'Saldo (Transaksi)'!D:D, $D7, 'Saldo (Transaksi)'!A:A, $F$12), TRUE, SUMIFS('Saldo (Transaksi)'!F:F, 'Saldo (Transaksi)'!D:D, $D7)) -> 0 | F7: =IFS($D$12="Hari Ini", SUMIFS('Saldo (Transaksi)'!F:F, 'Saldo (Transaksi)'!E:E, $D7, 'Saldo (Transaksi)'!A:A, TODAY()), $D$12="Bulan Ini", SUMIFS('Saldo (Transaksi)'!F:F, 'Saldo (Transaksi)'!E:E, $D7, 'Saldo (Transaksi)'!A:A, ">="&EOMONTH(TODAY(), -1)+1, 'Saldo (Transaksi)'!A:A, "<="&EOMONTH(TODAY(), 0)), $D$12="Pilih Tanggal", SUMIFS('Saldo (Transaksi)'!F:F, 'Saldo (Transaksi)'!E:E, $D7, 'Saldo (Transaksi)'!A:A, $F$12), TRUE, SUMIFS('Saldo (Transaksi)'!F:F, 'Saldo (Transaksi)'!E:E, $D7)) -> 0 | G7: =SUMIFS('Saldo (Transaksi)'!F:F, 'Saldo (Transaksi)'!D:D, $D7) - SUMIFS('Saldo (Transaksi)'!F:F, 'Saldo (Transaksi)'!E:E, $D7) -> 0
D8: WAHANA | E8: =IFS($D$12="Hari Ini", SUMIFS('Saldo (Transaksi)'!F:F, 'Saldo (Transaksi)'!D:D, $D8, 'Saldo (Transaksi)'!A:A, TODAY()), $D$12="Bulan Ini", SUMIFS('Saldo (Transaksi)'!F:F, 'Saldo (Transaksi)'!D:D, $D8, 'Saldo (Transaksi)'!A:A, ">="&EOMONTH(TODAY(), -1)+1, 'Saldo (Transaksi)'!A:A, "<="&EOMONTH(TODAY(), 0)), $D$12="Pilih Tanggal", SUMIFS('Saldo (Transaksi)'!F:F, 'Saldo (Transaksi)'!D:D, $D8, 'Saldo (Transaksi)'!A:A, $F$12), TRUE, SUMIFS('Saldo (Transaksi)'!F:F, 'Saldo (Transaksi)'!D:D, $D8)) -> 0 | F8: =IFS($D$12="Hari Ini", SUMIFS('Saldo (Transaksi)'!F:F, 'Saldo (Transaksi)'!E:E, $D8, 'Saldo (Transaksi)'!A:A, TODAY()), $D$12="Bulan Ini", SUMIFS('Saldo (Transaksi)'!F:F, 'Saldo (Transaksi)'!E:E, $D8, 'Saldo (Transaksi)'!A:A, ">="&EOMONTH(TODAY(), -1)+1, 'Saldo (Transaksi)'!A:A, "<="&EOMONTH(TODAY(), 0)), $D$12="Pilih Tanggal", SUMIFS('Saldo (Transaksi)'!F:F, 'Saldo (Transaksi)'!E:E, $D8, 'Saldo (Transaksi)'!A:A, $F$12), TRUE, SUMIFS('Saldo (Transaksi)'!F:F, 'Saldo (Transaksi)'!E:E, $D8)) -> 0 | G8: =SUMIFS('Saldo (Transaksi)'!F:F, 'Saldo (Transaksi)'!D:D, $D8) - SUMIFS('Saldo (Transaksi)'!F:F, 'Saldo (Transaksi)'!E:E, $D8) -> 0
D9: QRIS | E9: =IFS($D$12="Hari Ini", SUMIFS('Saldo (Transaksi)'!F:F, 'Saldo (Transaksi)'!D:D, $D9, 'Saldo (Transaksi)'!A:A, TODAY()), $D$12="Bulan Ini", SUMIFS('Saldo (Transaksi)'!F:F, 'Saldo (Transaksi)'!D:D, $D9, 'Saldo (Transaksi)'!A:A, ">="&EOMONTH(TODAY(), -1)+1, 'Saldo (Transaksi)'!A:A, "<="&EOMONTH(TODAY(), 0)), $D$12="Pilih Tanggal", SUMIFS('Saldo (Transaksi)'!F:F, 'Saldo (Transaksi)'!D:D, $D9, 'Saldo (Transaksi)'!A:A, $F$12), TRUE, SUMIFS('Saldo (Transaksi)'!F:F, 'Saldo (Transaksi)'!D:D, $D9)) -> 0 | F9: =IFS($D$12="Hari Ini", SUMIFS('Saldo (Transaksi)'!F:F, 'Saldo (Transaksi)'!E:E, $D9, 'Saldo (Transaksi)'!A:A, TODAY()), $D$12="Bulan Ini", SUMIFS('Saldo (Transaksi)'!F:F, 'Saldo (Transaksi)'!E:E, $D9, 'Saldo (Transaksi)'!A:A, ">="&EOMONTH(TODAY(), -1)+1, 'Saldo (Transaksi)'!A:A, "<="&EOMONTH(TODAY(), 0)), $D$12="Pilih Tanggal", SUMIFS('Saldo (Transaksi)'!F:F, 'Saldo (Transaksi)'!E:E, $D9, 'Saldo (Transaksi)'!A:A, $F$12), TRUE, SUMIFS('Saldo (Transaksi)'!F:F, 'Saldo (Transaksi)'!E:E, $D9)) -> 0 | G9: =SUMIFS('Saldo (Transaksi)'!F:F, 'Saldo (Transaksi)'!D:D, $D9) - SUMIFS('Saldo (Transaksi)'!F:F, 'Saldo (Transaksi)'!E:E, $D9) -> 0
D10: BANK BCA | E10: =IFS($D$12="Hari Ini", SUMIFS('Saldo (Transaksi)'!F:F, 'Saldo (Transaksi)'!D:D, $D10, 'Saldo (Transaksi)'!A:A, TODAY()), $D$12="Bulan Ini", SUMIFS('Saldo (Transaksi)'!F:F, 'Saldo (Transaksi)'!D:D, $D10, 'Saldo (Transaksi)'!A:A, ">="&EOMONTH(TODAY(), -1)+1, 'Saldo (Transaksi)'!A:A, "<="&EOMONTH(TODAY(), 0)), $D$12="Pilih Tanggal", SUMIFS('Saldo (Transaksi)'!F:F, 'Saldo (Transaksi)'!D:D, $D10, 'Saldo (Transaksi)'!A:A, $F$12), TRUE, SUMIFS('Saldo (Transaksi)'!F:F, 'Saldo (Transaksi)'!D:D, $D10)) -> 0 | F10: =IFS($D$12="Hari Ini", SUMIFS('Saldo (Transaksi)'!F:F, 'Saldo (Transaksi)'!E:E, $D10, 'Saldo (Transaksi)'!A:A, TODAY()), $D$12="Bulan Ini", SUMIFS('Saldo (Transaksi)'!F:F, 'Saldo (Transaksi)'!E:E, $D10, 'Saldo (Transaksi)'!A:A, ">="&EOMONTH(TODAY(), -1)+1, 'Saldo (Transaksi)'!A:A, "<="&EOMONTH(TODAY(), 0)), $D$12="Pilih Tanggal", SUMIFS('Saldo (Transaksi)'!F:F, 'Saldo (Transaksi)'!E:E, $D10, 'Saldo (Transaksi)'!A:A, $F$12), TRUE, SUMIFS('Saldo (Transaksi)'!F:F, 'Saldo (Transaksi)'!E:E, $D10)) -> 0 | G10: =SUMIFS('Saldo (Transaksi)'!F:F, 'Saldo (Transaksi)'!D:D, $D10) - SUMIFS('Saldo (Transaksi)'!F:F, 'Saldo (Transaksi)'!E:E, $D10) -> 0
D12: Pilih Tanggal | F12: 46223

Sheet Transaksi Harian
A1: Tanggal | B1: Kode Produk | C1: Nama Barang/Layanan | D1: Kategori | E1: Jenis | F1: Merk | G1: QTY | H1: Harga Modal | I1: Modal Via | J1: Harga Jual | K1: Metode Pembayaran | L1: Status Transaksi

Sheet Saldo (Transaksi)
A1: Tanggal | B1: Nama Transaksi | C1: Jenis | D1: Akun Tujuan | E1: Akun Asal | F1: Nominal

Sheet Laporan Harian
B1: Tanggal | C1: Total Transaksi | D1: Total Modal | E1: Total Penjualan | F1: Total Margin | H1: Cash | I1: Dana | J1: Transfer (BCA) | K1: QRIS
B2: {=SEQUENCE(31, 1, DATE(2026, 7, 1))} -> 46204 | C2: =COUNTIFS('Transaksi Harian'!$A:$A, ">="&$B2, 'Transaksi Harian'!$A:$A, "<"&($B2+1)) -> 0 | D2: =SUMIFS('Transaksi Harian'!$H:$H, 'Transaksi Harian'!$A:$A, ">="&$B2, 'Transaksi Harian'!$A:$A, "<"&($B2+1)) -> 0 | E2: =SUMIFS('Transaksi Harian'!$J:$J, 'Transaksi Harian'!$A:$A, ">="&$B2, 'Transaksi Harian'!$A:$A, "<"&($B2+1)) -> 0 | F2: =E2-D2 -> 0 | H2: =SUMIFS('Transaksi Harian'!$J:$J, 'Transaksi Harian'!$A:$A, ">="&$B2, 'Transaksi Harian'!$A:$A, "<"&($B2+1), 'Transaksi Harian'!$K:$K, TRIM(H$1)) -> 0 | I2: =SUMIFS('Transaksi Harian'!$J:$J, 'Transaksi Harian'!$A:$A, ">="&$B2, 'Transaksi Harian'!$A:$A, "<"&($B2+1), 'Transaksi Harian'!$K:$K, TRIM(I$1)) -> 0 | J2: =SUMIFS('Transaksi Harian'!$J:$J, 'Transaksi Harian'!$A:$A, ">="&$B2, 'Transaksi Harian'!$A:$A, "<"&($B2+1), 'Transaksi Harian'!$K:$K, "TRANSFER") -> 0 | K2: =SUMIFS('Transaksi Harian'!$J:$J, 'Transaksi Harian'!$A:$A, ">="&$B2, 'Transaksi Harian'!$A:$A, "<"&($B2+1), 'Transaksi Harian'!$K:$K, TRIM(K$1)) -> 0
B3: 46205 | C3: =COUNTIFS('Transaksi Harian'!$A:$A, ">="&$B3, 'Transaksi Harian'!$A:$A, "<"&($B3+1)) -> 0 | D3: =SUMIFS('Transaksi Harian'!$H:$H, 'Transaksi Harian'!$A:$A, ">="&$B3, 'Transaksi Harian'!$A:$A, "<"&($B3+1)) -> 0 | E3: =SUMIFS('Transaksi Harian'!$J:$J, 'Transaksi Harian'!$A:$A, ">="&$B3, 'Transaksi Harian'!$A:$A, "<"&($B3+1)) -> 0 | F3: =E3-D3 -> 0 | H3: =SUMIFS('Transaksi Harian'!$J:$J, 'Transaksi Harian'!$A:$A, ">="&$B3, 'Transaksi Harian'!$A:$A, "<"&($B3+1), 'Transaksi Harian'!$K:$K, TRIM(H$1)) -> 0 | I3: =SUMIFS('Transaksi Harian'!$J:$J, 'Transaksi Harian'!$A:$A, ">="&$B3, 'Transaksi Harian'!$A:$A, "<"&($B3+1), 'Transaksi Harian'!$K:$K, TRIM(I$1)) -> 0 | J3: =SUMIFS('Transaksi Harian'!$J:$J, 'Transaksi Harian'!$A:$A, ">="&$B3, 'Transaksi Harian'!$A:$A, "<"&($B3+1), 'Transaksi Harian'!$K:$K, "TRANSFER") -> 0 | K3: =SUMIFS('Transaksi Harian'!$J:$J, 'Transaksi Harian'!$A:$A, ">="&$B3, 'Transaksi Harian'!$A:$A, "<"&($B3+1), 'Transaksi Harian'!$K:$K, TRIM(K$1)) -> 0
B4: 46206 | C4: =COUNTIFS('Transaksi Harian'!$A:$A, ">="&$B4, 'Transaksi Harian'!$A:$A, "<"&($B4+1)) -> 0 | D4: =SUMIFS('Transaksi Harian'!$H:$H, 'Transaksi Harian'!$A:$A, ">="&$B4, 'Transaksi Harian'!$A:$A, "<"&($B4+1)) -> 0 | E4: =SUMIFS('Transaksi Harian'!$J:$J, 'Transaksi Harian'!$A:$A, ">="&$B4, 'Transaksi Harian'!$A:$A, "<"&($B4+1)) -> 0 | F4: =E4-D4 -> 0 | H4: =SUMIFS('Transaksi Harian'!$J:$J, 'Transaksi Harian'!$A:$A, ">="&$B4, 'Transaksi Harian'!$A:$A, "<"&($B4+1), 'Transaksi Harian'!$K:$K, TRIM(H$1)) -> 0 | I4: =SUMIFS('Transaksi Harian'!$J:$J, 'Transaksi Harian'!$A:$A, ">="&$B4, 'Transaksi Harian'!$A:$A, "<"&($B4+1), 'Transaksi Harian'!$K:$K, TRIM(I$1)) -> 0 | J4: =SUMIFS('Transaksi Harian'!$J:$J, 'Transaksi Harian'!$A:$A, ">="&$B4, 'Transaksi Harian'!$A:$A, "<"&($B4+1), 'Transaksi Harian'!$K:$K, "TRANSFER") -> 0 | K4: =SUMIFS('Transaksi Harian'!$J:$J, 'Transaksi Harian'!$A:$A, ">="&$B4, 'Transaksi Harian'!$A:$A, "<"&($B4+1), 'Transaksi Harian'!$K:$K, TRIM(K$1)) -> 0
B5: 46207 | C5: =COUNTIFS('Transaksi Harian'!$A:$A, ">="&$B5, 'Transaksi Harian'!$A:$A, "<"&($B5+1)) -> 0 | D5: =SUMIFS('Transaksi Harian'!$H:$H, 'Transaksi Harian'!$A:$A, ">="&$B5, 'Transaksi Harian'!$A:$A, "<"&($B5+1)) -> 0 | E5: =SUMIFS('Transaksi Harian'!$J:$J, 'Transaksi Harian'!$A:$A, ">="&$B5, 'Transaksi Harian'!$A:$A, "<"&($B5+1)) -> 0 | F5: =E5-D5 -> 0 | H5: =SUMIFS('Transaksi Harian'!$J:$J, 'Transaksi Harian'!$A:$A, ">="&$B5, 'Transaksi Harian'!$A:$A, "<"&($B5+1), 'Transaksi Harian'!$K:$K, TRIM(H$1)) -> 0 | I5: =SUMIFS('Transaksi Harian'!$J:$J, 'Transaksi Harian'!$A:$A, ">="&$B5, 'Transaksi Harian'!$A:$A, "<"&($B5+1), 'Transaksi Harian'!$K:$K, TRIM(I$1)) -> 0 | J5: =SUMIFS('Transaksi Harian'!$J:$J, 'Transaksi Harian'!$A:$A, ">="&$B5, 'Transaksi Harian'!$A:$A, "<"&($B5+1), 'Transaksi Harian'!$K:$K, "TRANSFER") -> 0 | K5: =SUMIFS('Transaksi Harian'!$J:$J, 'Transaksi Harian'!$A:$A, ">="&$B5, 'Transaksi Harian'!$A:$A, "<"&($B5+1), 'Transaksi Harian'!$K:$K, TRIM(K$1)) -> 0
B6: 46208 | C6: =COUNTIFS('Transaksi Harian'!$A:$A, ">="&$B6, 'Transaksi Harian'!$A:$A, "<"&($B6+1)) -> 0 | D6: =SUMIFS('Transaksi Harian'!$H:$H, 'Transaksi Harian'!$A:$A, ">="&$B6, 'Transaksi Harian'!$A:$A, "<"&($B6+1)) -> 0 | E6: =SUMIFS('Transaksi Harian'!$J:$J, 'Transaksi Harian'!$A:$A, ">="&$B6, 'Transaksi Harian'!$A:$A, "<"&($B6+1)) -> 0 | F6: =E6-D6 -> 0 | H6: =SUMIFS('Transaksi Harian'!$J:$J, 'Transaksi Harian'!$A:$A, ">="&$B6, 'Transaksi Harian'!$A:$A, "<"&($B6+1), 'Transaksi Harian'!$K:$K, TRIM(H$1)) -> 0 | I6: =SUMIFS('Transaksi Harian'!$J:$J, 'Transaksi Harian'!$A:$A, ">="&$B6, 'Transaksi Harian'!$A:$A, "<"&($B6+1), 'Transaksi Harian'!$K:$K, TRIM(I$1)) -> 0 | J6: =SUMIFS('Transaksi Harian'!$J:$J, 'Transaksi Harian'!$A:$A, ">="&$B6, 'Transaksi Harian'!$A:$A, "<"&($B6+1), 'Transaksi Harian'!$K:$K, "TRANSFER") -> 0 | K6: =SUMIFS('Transaksi Harian'!$J:$J, 'Transaksi Harian'!$A:$A, ">="&$B6, 'Transaksi Harian'!$A:$A, "<"&($B6+1), 'Transaksi Harian'!$K:$K, TRIM(K$1)) -> 0
B7: 46209 | C7: =COUNTIFS('Transaksi Harian'!$A:$A, ">="&$B7, 'Transaksi Harian'!$A:$A, "<"&($B7+1)) -> 0 | D7: =SUMIFS('Transaksi Harian'!$H:$H, 'Transaksi Harian'!$A:$A, ">="&$B7, 'Transaksi Harian'!$A:$A, "<"&($B7+1)) -> 0 | E7: =SUMIFS('Transaksi Harian'!$J:$J, 'Transaksi Harian'!$A:$A, ">="&$B7, 'Transaksi Harian'!$A:$A, "<"&($B7+1)) -> 0 | F7: =E7-D7 -> 0 | H7: =SUMIFS('Transaksi Harian'!$J:$J, 'Transaksi Harian'!$A:$A, ">="&$B7, 'Transaksi Harian'!$A:$A, "<"&($B7+1), 'Transaksi Harian'!$K:$K, TRIM(H$1)) -> 0 | I7: =SUMIFS('Transaksi Harian'!$J:$J, 'Transaksi Harian'!$A:$A, ">="&$B7, 'Transaksi Harian'!$A:$A, "<"&($B7+1), 'Transaksi Harian'!$K:$K, TRIM(I$1)) -> 0 | J7: =SUMIFS('Transaksi Harian'!$J:$J, 'Transaksi Harian'!$A:$A, ">="&$B7, 'Transaksi Harian'!$A:$A, "<"&($B7+1), 'Transaksi Harian'!$K:$K, "TRANSFER") -> 0 | K7: =SUMIFS('Transaksi Harian'!$J:$J, 'Transaksi Harian'!$A:$A, ">="&$B7, 'Transaksi Harian'!$A:$A, "<"&($B7+1), 'Transaksi Harian'!$K:$K, TRIM(K$1)) -> 0
B8: 46210 | C8: =COUNTIFS('Transaksi Harian'!$A:$A, ">="&$B8, 'Transaksi Harian'!$A:$A, "<"&($B8+1)) -> 0 | D8: =SUMIFS('Transaksi Harian'!$H:$H, 'Transaksi Harian'!$A:$A, ">="&$B8, 'Transaksi Harian'!$A:$A, "<"&($B8+1)) -> 0 | E8: =SUMIFS('Transaksi Harian'!$J:$J, 'Transaksi Harian'!$A:$A, ">="&$B8, 'Transaksi Harian'!$A:$A, "<"&($B8+1)) -> 0 | F8: =E8-D8 -> 0 | H8: =SUMIFS('Transaksi Harian'!$J:$J, 'Transaksi Harian'!$A:$A, ">="&$B8, 'Transaksi Harian'!$A:$A, "<"&($B8+1), 'Transaksi Harian'!$K:$K, TRIM(H$1)) -> 0 | I8: =SUMIFS('Transaksi Harian'!$J:$J, 'Transaksi Harian'!$A:$A, ">="&$B8, 'Transaksi Harian'!$A:$A, "<"&($B8+1), 'Transaksi Harian'!$K:$K, TRIM(I$1)) -> 0 | J8: =SUMIFS('Transaksi Harian'!$J:$J, 'Transaksi Harian'!$A:$A, ">="&$B8, 'Transaksi Harian'!$A:$A, "<"&($B8+1), 'Transaksi Harian'!$K:$K, "TRANSFER") -> 0 | K8: =SUMIFS('Transaksi Harian'!$J:$J, 'Transaksi Harian'!$A:$A, ">="&$B8, 'Transaksi Harian'!$A:$A, "<"&($B8+1), 'Transaksi Harian'!$K:$K, TRIM(K$1)) -> 0
B9: 46211 | C9: =COUNTIFS('Transaksi Harian'!$A:$A, ">="&$B9, 'Transaksi Harian'!$A:$A, "<"&($B9+1)) -> 0 | D9: =SUMIFS('Transaksi Harian'!$H:$H, 'Transaksi Harian'!$A:$A, ">="&$B9, 'Transaksi Harian'!$A:$A, "<"&($B9+1)) -> 0 | E9: =SUMIFS('Transaksi Harian'!$J:$J, 'Transaksi Harian'!$A:$A, ">="&$B9, 'Transaksi Harian'!$A:$A, "<"&($B9+1)) -> 0 | F9: =E9-D9 -> 0 | H9: =SUMIFS('Transaksi Harian'!$J:$J, 'Transaksi Harian'!$A:$A, ">="&$B9, 'Transaksi Harian'!$A:$A, "<"&($B9+1), 'Transaksi Harian'!$K:$K, TRIM(H$1)) -> 0 | I9: =SUMIFS('Transaksi Harian'!$J:$J, 'Transaksi Harian'!$A:$A, ">="&$B9, 'Transaksi Harian'!$A:$A, "<"&($B9+1), 'Transaksi Harian'!$K:$K, TRIM(I$1)) -> 0 | J9: =SUMIFS('Transaksi Harian'!$J:$J, 'Transaksi Harian'!$A:$A, ">="&$B9, 'Transaksi Harian'!$A:$A, "<"&($B9+1), 'Transaksi Harian'!$K:$K, "TRANSFER") -> 0 | K9: =SUMIFS('Transaksi Harian'!$J:$J, 'Transaksi Harian'!$A:$A, ">="&$B9, 'Transaksi Harian'!$A:$A, "<"&($B9+1), 'Transaksi Harian'!$K:$K, TRIM(K$1)) -> 0
B10: 46212 | C10: =COUNTIFS('Transaksi Harian'!$A:$A, ">="&$B10, 'Transaksi Harian'!$A:$A, "<"&($B10+1)) -> 0 | D10: =SUMIFS('Transaksi Harian'!$H:$H, 'Transaksi Harian'!$A:$A, ">="&$B10, 'Transaksi Harian'!$A:$A, "<"&($B10+1)) -> 0 | E10: =SUMIFS('Transaksi Harian'!$J:$J, 'Transaksi Harian'!$A:$A, ">="&$B10, 'Transaksi Harian'!$A:$A, "<"&($B10+1)) -> 0 | F10: =E10-D10 -> 0 | H10: =SUMIFS('Transaksi Harian'!$J:$J, 'Transaksi Harian'!$A:$A, ">="&$B10, 'Transaksi Harian'!$A:$A, "<"&($B10+1), 'Transaksi Harian'!$K:$K, TRIM(H$1)) -> 0 | I10: =SUMIFS('Transaksi Harian'!$J:$J, 'Transaksi Harian'!$A:$A, ">="&$B10, 'Transaksi Harian'!$A:$A, "<"&($B10+1), 'Transaksi Harian'!$K:$K, TRIM(I$1)) -> 0 | J10: =SUMIFS('Transaksi Harian'!$J:$J, 'Transaksi Harian'!$A:$A, ">="&$B10, 'Transaksi Harian'!$A:$A, "<"&($B10+1), 'Transaksi Harian'!$K:$K, "TRANSFER") -> 0 | K10: =SUMIFS('Transaksi Harian'!$J:$J, 'Transaksi Harian'!$A:$A, ">="&$B10, 'Transaksi Harian'!$A:$A, "<"&($B10+1), 'Transaksi Harian'!$K:$K, TRIM(K$1)) -> 0
B11: 46213 | C11: =COUNTIFS('Transaksi Harian'!$A:$A, ">="&$B11, 'Transaksi Harian'!$A:$A, "<"&($B11+1)) -> 0 | D11: =SUMIFS('Transaksi Harian'!$H:$H, 'Transaksi Harian'!$A:$A, ">="&$B11, 'Transaksi Harian'!$A:$A, "<"&($B11+1)) -> 0 | E11: =SUMIFS('Transaksi Harian'!$J:$J, 'Transaksi Harian'!$A:$A, ">="&$B11, 'Transaksi Harian'!$A:$A, "<"&($B11+1)) -> 0 | F11: =E11-D11 -> 0 | H11: =SUMIFS('Transaksi Harian'!$J:$J, 'Transaksi Harian'!$A:$A, ">="&$B11, 'Transaksi Harian'!$A:$A, "<"&($B11+1), 'Transaksi Harian'!$K:$K, TRIM(H$1)) -> 0 | I11: =SUMIFS('Transaksi Harian'!$J:$J, 'Transaksi Harian'!$A:$A, ">="&$B11, 'Transaksi Harian'!$A:$A, "<"&($B11+1), 'Transaksi Harian'!$K:$K, TRIM(I$1)) -> 0 | J11: =SUMIFS('Transaksi Harian'!$J:$J, 'Transaksi Harian'!$A:$A, ">="&$B11, 'Transaksi Harian'!$A:$A, "<"&($B11+1), 'Transaksi Harian'!$K:$K, "TRANSFER") -> 0 | K11: =SUMIFS('Transaksi Harian'!$J:$J, 'Transaksi Harian'!$A:$A, ">="&$B11, 'Transaksi Harian'!$A:$A, "<"&($B11+1), 'Transaksi Harian'!$K:$K, TRIM(K$1)) -> 0
B12: 46214 | C12: =COUNTIFS('Transaksi Harian'!$A:$A, ">="&$B12, 'Transaksi Harian'!$A:$A, "<"&($B12+1)) -> 0 | D12: =SUMIFS('Transaksi Harian'!$H:$H, 'Transaksi Harian'!$A:$A, ">="&$B12, 'Transaksi Harian'!$A:$A, "<"&($B12+1)) -> 0 | E12: =SUMIFS('Transaksi Harian'!$J:$J, 'Transaksi Harian'!$A:$A, ">="&$B12, 'Transaksi Harian'!$A:$A, "<"&($B12+1)) -> 0 | F12: =E12-D12 -> 0 | H12: =SUMIFS('Transaksi Harian'!$J:$J, 'Transaksi Harian'!$A:$A, ">="&$B12, 'Transaksi Harian'!$A:$A, "<"&($B12+1), 'Transaksi Harian'!$K:$K, TRIM(H$1)) -> 0 | I12: =SUMIFS('Transaksi Harian'!$J:$J, 'Transaksi Harian'!$A:$A, ">="&$B12, 'Transaksi Harian'!$A:$A, "<"&($B12+1), 'Transaksi Harian'!$K:$K, TRIM(I$1)) -> 0 | J12: =SUMIFS('Transaksi Harian'!$J:$J, 'Transaksi Harian'!$A:$A, ">="&$B12, 'Transaksi Harian'!$A:$A, "<"&($B12+1), 'Transaksi Harian'!$K:$K, "TRANSFER") -> 0 | K12: =SUMIFS('Transaksi Harian'!$J:$J, 'Transaksi Harian'!$A:$A, ">="&$B12, 'Transaksi Harian'!$A:$A, "<"&($B12+1), 'Transaksi Harian'!$K:$K, TRIM(K$1)) -> 0
B13: 46215 | C13: =COUNTIFS('Transaksi Harian'!$A:$A, ">="&$B13, 'Transaksi Harian'!$A:$A, "<"&($B13+1)) -> 0 | D13: =SUMIFS('Transaksi Harian'!$H:$H, 'Transaksi Harian'!$A:$A, ">="&$B13, 'Transaksi Harian'!$A:$A, "<"&($B13+1)) -> 0 | E13: =SUMIFS('Transaksi Harian'!$J:$J, 'Transaksi Harian'!$A:$A, ">="&$B13, 'Transaksi Harian'!$A:$A, "<"&($B13+1)) -> 0 | F13: =E13-D13 -> 0 | H13: =SUMIFS('Transaksi Harian'!$J:$J, 'Transaksi Harian'!$A:$A, ">="&$B13, 'Transaksi Harian'!$A:$A, "<"&($B13+1), 'Transaksi Harian'!$K:$K, TRIM(H$1)) -> 0 | I13: =SUMIFS('Transaksi Harian'!$J:$J, 'Transaksi Harian'!$A:$A, ">="&$B13, 'Transaksi Harian'!$A:$A, "<"&($B13+1), 'Transaksi Harian'!$K:$K, TRIM(I$1)) -> 0 | J13: =SUMIFS('Transaksi Harian'!$J:$J, 'Transaksi Harian'!$A:$A, ">="&$B13, 'Transaksi Harian'!$A:$A, "<"&($B13+1), 'Transaksi Harian'!$K:$K, "TRANSFER") -> 0 | K13: =SUMIFS('Transaksi Harian'!$J:$J, 'Transaksi Harian'!$A:$A, ">="&$B13, 'Transaksi Harian'!$A:$A, "<"&($B13+1), 'Transaksi Harian'!$K:$K, TRIM(K$1)) -> 0
B14: 46216 | C14: =COUNTIFS('Transaksi Harian'!$A:$A, ">="&$B14, 'Transaksi Harian'!$A:$A, "<"&($B14+1)) -> 0 | D14: =SUMIFS('Transaksi Harian'!$H:$H, 'Transaksi Harian'!$A:$A, ">="&$B14, 'Transaksi Harian'!$A:$A, "<"&($B14+1)) -> 0 | E14: =SUMIFS('Transaksi Harian'!$J:$J, 'Transaksi Harian'!$A:$A, ">="&$B14, 'Transaksi Harian'!$A:$A, "<"&($B14+1)) -> 0 | F14: =E14-D14 -> 0 | H14: =SUMIFS('Transaksi Harian'!$J:$J, 'Transaksi Harian'!$A:$A, ">="&$B14, 'Transaksi Harian'!$A:$A, "<"&($B14+1), 'Transaksi Harian'!$K:$K, TRIM(H$1)) -> 0 | I14: =SUMIFS('Transaksi Harian'!$J:$J, 'Transaksi Harian'!$A:$A, ">="&$B14, 'Transaksi Harian'!$A:$A, "<"&($B14+1), 'Transaksi Harian'!$K:$K, TRIM(I$1)) -> 0 | J14: =SUMIFS('Transaksi Harian'!$J:$J, 'Transaksi Harian'!$A:$A, ">="&$B14, 'Transaksi Harian'!$A:$A, "<"&($B14+1), 'Transaksi Harian'!$K:$K, "TRANSFER") -> 0 | K14: =SUMIFS('Transaksi Harian'!$J:$J, 'Transaksi Harian'!$A:$A, ">="&$B14, 'Transaksi Harian'!$A:$A, "<"&($B14+1), 'Transaksi Harian'!$K:$K, TRIM(K$1)) -> 0
... B32: 46234 | C32: =COUNTIFS('Transaksi Harian'!$A:$A, ">="&$B32, 'Transaksi Harian'!$A:$A, "<"&($B32+1)) -> 0 | D32: =SUMIFS('Transaksi Harian'!$H:$H, 'Transaksi Harian'!$A:$A, ">="&$B32, 'Transaksi Harian'!$A:$A, "<"&($B32+1)) -> 0 | E32: =SUMIFS('Transaksi Harian'!$J:$J, 'Transaksi Harian'!$A:$A, ">="&$B32, 'Transaksi Harian'!$A:$A, "<"&($B32+1)) -> 0 | F32: =E32-D32 -> 0 | H32: =SUMIFS('Transaksi Harian'!$J:$J, 'Transaksi Harian'!$A:$A, ">="&$B32, 'Transaksi Harian'!$A:$A, "<"&($B32+1), 'Transaksi Harian'!$K:$K, TRIM(H$1)) -> 0 | I32: =SUMIFS('Transaksi Harian'!$J:$J, 'Transaksi Harian'!$A:$A, ">="&$B32, 'Transaksi Harian'!$A:$A, "<"&($B32+1), 'Transaksi Harian'!$K:$K, TRIM(I$1)) -> 0 | J32: =SUMIFS('Transaksi Harian'!$J:$J, 'Transaksi Harian'!$A:$A, ">="&$B32, 'Transaksi Harian'!$A:$A, "<"&($B32+1), 'Transaksi Harian'!$K:$K, "TRANSFER") -> 0 | K32: =SUMIFS('Transaksi Harian'!$J:$J, 'Transaksi Harian'!$A:$A, ">="&$B32, 'Transaksi Harian'!$A:$A, "<"&($B32+1), 'Transaksi Harian'!$K:$K, TRIM(K$1)) -> 0
C36: TOTAL MARGIN
C37: TOTAL TRANSAKSI

Sheet Laporan Bulanan
B1: Tanggal | C1: Total Transaksi | D1: Aksesoris | E1: Multi | F1: Transfer | G1: Lain-lain | H1: Margin Penjualan
B2: 46174 | C2: =COUNTIFS('Transaksi Harian'!$A:$A, ">="&$B2, 'Transaksi Harian'!$A:$A, "<"&($B2+1)) -> 0 | D2: =SUMIFS('Transaksi Harian'!$J:$J, 'Transaksi Harian'!$A:$A, ">="&$B2, 'Transaksi Harian'!$A:$A, "<"&($B2+1), 'Transaksi Harian'!$D:$D, TRIM(D$1)) -> 0 | E2: =SUMIFS('Transaksi Harian'!$J:$J, 'Transaksi Harian'!$A:$A, ">="&$B2, 'Transaksi Harian'!$A:$A, "<"&($B2+1), 'Transaksi Harian'!$D:$D, TRIM(E$1)) -> 0 | F2: =SUMIFS('Transaksi Harian'!$J:$J, 'Transaksi Harian'!$A:$A, ">="&$B2, 'Transaksi Harian'!$A:$A, "<"&($B2+1), 'Transaksi Harian'!$D:$D, TRIM(F$1)) -> 0 | G2: =SUMIFS('Transaksi Harian'!$J:$J, 'Transaksi Harian'!$A:$A, ">="&$B2, 'Transaksi Harian'!$A:$A, "<"&($B2+1), 'Transaksi Harian'!$D:$D, TRIM(G$1)) -> 0 | H2: =SUMIFS('Transaksi Harian'!$J:$J, 'Transaksi Harian'!$A:$A, ">="&$B2, 'Transaksi Harian'!$A:$A, "<"&($B2+1)) - SUMIFS('Transaksi Harian'!$H:$H, 'Transaksi Harian'!$A:$A, ">="&$B2, 'Transaksi Harian'!$A:$A, "<"&($B2+1)) -> 0
B3: 46175 | C3: =COUNTIFS('Transaksi Harian'!$A:$A, ">="&$B3, 'Transaksi Harian'!$A:$A, "<"&($B3+1)) -> 0 | D3: =SUMIFS('Transaksi Harian'!$J:$J, 'Transaksi Harian'!$A:$A, ">="&$B3, 'Transaksi Harian'!$A:$A, "<"&($B3+1), 'Transaksi Harian'!$D:$D, TRIM(D$1)) -> 0 | E3: =SUMIFS('Transaksi Harian'!$J:$J, 'Transaksi Harian'!$A:$A, ">="&$B3, 'Transaksi Harian'!$A:$A, "<"&($B3+1), 'Transaksi Harian'!$D:$D, TRIM(E$1)) -> 0 | F3: =SUMIFS('Transaksi Harian'!$J:$J, 'Transaksi Harian'!$A:$A, ">="&$B3, 'Transaksi Harian'!$A:$A, "<"&($B3+1), 'Transaksi Harian'!$D:$D, TRIM(F$1)) -> 0 | G3: =SUMIFS('Transaksi Harian'!$J:$J, 'Transaksi Harian'!$A:$A, ">="&$B3, 'Transaksi Harian'!$A:$A, "<"&($B3+1), 'Transaksi Harian'!$D:$D, TRIM(G$1)) -> 0 | H3: =SUMIFS('Transaksi Harian'!$J:$J, 'Transaksi Harian'!$A:$A, ">="&$B3, 'Transaksi Harian'!$A:$A, "<"&($B3+1)) - SUMIFS('Transaksi Harian'!$H:$H, 'Transaksi Harian'!$A:$A, ">="&$B3, 'Transaksi Harian'!$A:$A, "<"&($B3+1)) -> 0
B4: 46176 | C4: =COUNTIFS('Transaksi Harian'!$A:$A, ">="&$B4, 'Transaksi Harian'!$A:$A, "<"&($B4+1)) -> 0 | D4: =SUMIFS('Transaksi Harian'!$J:$J, 'Transaksi Harian'!$A:$A, ">="&$B4, 'Transaksi Harian'!$A:$A, "<"&($B4+1), 'Transaksi Harian'!$D:$D, TRIM(D$1)) -> 0 | E4: =SUMIFS('Transaksi Harian'!$J:$J, 'Transaksi Harian'!$A:$A, ">="&$B4, 'Transaksi Harian'!$A:$A, "<"&($B4+1), 'Transaksi Harian'!$D:$D, TRIM(E$1)) -> 0 | F4: =SUMIFS('Transaksi Harian'!$J:$J, 'Transaksi Harian'!$A:$A, ">="&$B4, 'Transaksi Harian'!$A:$A, "<"&($B4+1), 'Transaksi Harian'!$D:$D, TRIM(F$1)) -> 0 | G4: =SUMIFS('Transaksi Harian'!$J:$J, 'Transaksi Harian'!$A:$A, ">="&$B4, 'Transaksi Harian'!$A:$A, "<"&($B4+1), 'Transaksi Harian'!$D:$D, TRIM(G$1)) -> 0 | H4: =SUMIFS('Transaksi Harian'!$J:$J, 'Transaksi Harian'!$A:$A, ">="&$B4, 'Transaksi Harian'!$A:$A, "<"&($B4+1)) - SUMIFS('Transaksi Harian'!$H:$H, 'Transaksi Harian'!$A:$A, ">="&$B4, 'Transaksi Harian'!$A:$A, "<"&($B4+1)) -> 0
B5: 46177 | C5: =COUNTIFS('Transaksi Harian'!$A:$A, ">="&$B5, 'Transaksi Harian'!$A:$A, "<"&($B5+1)) -> 0 | D5: =SUMIFS('Transaksi Harian'!$J:$J, 'Transaksi Harian'!$A:$A, ">="&$B5, 'Transaksi Harian'!$A:$A, "<"&($B5+1), 'Transaksi Harian'!$D:$D, TRIM(D$1)) -> 0 | E5: =SUMIFS('Transaksi Harian'!$J:$J, 'Transaksi Harian'!$A:$A, ">="&$B5, 'Transaksi Harian'!$A:$A, "<"&($B5+1), 'Transaksi Harian'!$D:$D, TRIM(E$1)) -> 0 | F5: =SUMIFS('Transaksi Harian'!$J:$J, 'Transaksi Harian'!$A:$A, ">="&$B5, 'Transaksi Harian'!$A:$A, "<"&($B5+1), 'Transaksi Harian'!$D:$D, TRIM(F$1)) -> 0 | G5: =SUMIFS('Transaksi Harian'!$J:$J, 'Transaksi Harian'!$A:$A, ">="&$B5, 'Transaksi Harian'!$A:$A, "<"&($B5+1), 'Transaksi Harian'!$D:$D, TRIM(G$1)) -> 0 | H5: =SUMIFS('Transaksi Harian'!$J:$J, 'Transaksi Harian'!$A:$A, ">="&$B5, 'Transaksi Harian'!$A:$A, "<"&($B5+1)) - SUMIFS('Transaksi Harian'!$H:$H, 'Transaksi Harian'!$A:$A, ">="&$B5, 'Transaksi Harian'!$A:$A, "<"&($B5+1)) -> 0
B6: 46178 | C6: =COUNTIFS('Transaksi Harian'!$A:$A, ">="&$B6, 'Transaksi Harian'!$A:$A, "<"&($B6+1)) -> 0 | D6: =SUMIFS('Transaksi Harian'!$J:$J, 'Transaksi Harian'!$A:$A, ">="&$B6, 'Transaksi Harian'!$A:$A, "<"&($B6+1), 'Transaksi Harian'!$D:$D, TRIM(D$1)) -> 0 | E6: =SUMIFS('Transaksi Harian'!$J:$J, 'Transaksi Harian'!$A:$A, ">="&$B6, 'Transaksi Harian'!$A:$A, "<"&($B6+1), 'Transaksi Harian'!$D:$D, TRIM(E$1)) -> 0 | F6: =SUMIFS('Transaksi Harian'!$J:$J, 'Transaksi Harian'!$A:$A, ">="&$B6, 'Transaksi Harian'!$A:$A, "<"&($B6+1), 'Transaksi Harian'!$D:$D, TRIM(F$1)) -> 0 | G6: =SUMIFS('Transaksi Harian'!$J:$J, 'Transaksi Harian'!$A:$A, ">="&$B6, 'Transaksi Harian'!$A:$A, "<"&($B6+1), 'Transaksi Harian'!$D:$D, TRIM(G$1)) -> 0 | H6: =SUMIFS('Transaksi Harian'!$J:$J, 'Transaksi Harian'!$A:$A, ">="&$B6, 'Transaksi Harian'!$A:$A, "<"&($B6+1)) - SUMIFS('Transaksi Harian'!$H:$H, 'Transaksi Harian'!$A:$A, ">="&$B6, 'Transaksi Harian'!$A:$A, "<"&($B6+1)) -> 0
B7: 46179 | C7: =COUNTIFS('Transaksi Harian'!$A:$A, ">="&$B7, 'Transaksi Harian'!$A:$A, "<"&($B7+1)) -> 0 | D7: =SUMIFS('Transaksi Harian'!$J:$J, 'Transaksi Harian'!$A:$A, ">="&$B7, 'Transaksi Harian'!$A:$A, "<"&($B7+1), 'Transaksi Harian'!$D:$D, TRIM(D$1)) -> 0 | E7: =SUMIFS('Transaksi Harian'!$J:$J, 'Transaksi Harian'!$A:$A, ">="&$B7, 'Transaksi Harian'!$A:$A, "<"&($B7+1), 'Transaksi Harian'!$D:$D, TRIM(E$1)) -> 0 | F7: =SUMIFS('Transaksi Harian'!$J:$J, 'Transaksi Harian'!$A:$A, ">="&$B7, 'Transaksi Harian'!$A:$A, "<"&($B7+1), 'Transaksi Harian'!$D:$D, TRIM(F$1)) -> 0 | G7: =SUMIFS('Transaksi Harian'!$J:$J, 'Transaksi Harian'!$A:$A, ">="&$B7, 'Transaksi Harian'!$A:$A, "<"&($B7+1), 'Transaksi Harian'!$D:$D, TRIM(G$1)) -> 0 | H7: =SUMIFS('Transaksi Harian'!$J:$J, 'Transaksi Harian'!$A:$A, ">="&$B7, 'Transaksi Harian'!$A:$A, "<"&($B7+1)) - SUMIFS('Transaksi Harian'!$H:$H, 'Transaksi Harian'!$A:$A, ">="&$B7, 'Transaksi Harian'!$A:$A, "<"&($B7+1)) -> 0
B8: 46180 | C8: =COUNTIFS('Transaksi Harian'!$A:$A, ">="&$B8, 'Transaksi Harian'!$A:$A, "<"&($B8+1)) -> 0 | D8: =SUMIFS('Transaksi Harian'!$J:$J, 'Transaksi Harian'!$A:$A, ">="&$B8, 'Transaksi Harian'!$A:$A, "<"&($B8+1), 'Transaksi Harian'!$D:$D, TRIM(D$1)) -> 0 | E8: =SUMIFS('Transaksi Harian'!$J:$J, 'Transaksi Harian'!$A:$A, ">="&$B8, 'Transaksi Harian'!$A:$A, "<"&($B8+1), 'Transaksi Harian'!$D:$D, TRIM(E$1)) -> 0 | F8: =SUMIFS('Transaksi Harian'!$J:$J, 'Transaksi Harian'!$A:$A, ">="&$B8, 'Transaksi Harian'!$A:$A, "<"&($B8+1), 'Transaksi Harian'!$D:$D, TRIM(F$1)) -> 0 | G8: =SUMIFS('Transaksi Harian'!$J:$J, 'Transaksi Harian'!$A:$A, ">="&$B8, 'Transaksi Harian'!$A:$A, "<"&($B8+1), 'Transaksi Harian'!$D:$D, TRIM(G$1)) -> 0 | H8: =SUMIFS('Transaksi Harian'!$J:$J, 'Transaksi Harian'!$A:$A, ">="&$B8, 'Transaksi Harian'!$A:$A, "<"&($B8+1)) - SUMIFS('Transaksi Harian'!$H:$H, 'Transaksi Harian'!$A:$A, ">="&$B8, 'Transaksi Harian'!$A:$A, "<"&($B8+1)) -> 0
B9: 46181 | C9: =COUNTIFS('Transaksi Harian'!$A:$A, ">="&$B9, 'Transaksi Harian'!$A:$A, "<"&($B9+1)) -> 0 | D9: =SUMIFS('Transaksi Harian'!$J:$J, 'Transaksi Harian'!$A:$A, ">="&$B9, 'Transaksi Harian'!$A:$A, "<"&($B9+1), 'Transaksi Harian'!$D:$D, TRIM(D$1)) -> 0 | E9: =SUMIFS('Transaksi Harian'!$J:$J, 'Transaksi Harian'!$A:$A, ">="&$B9, 'Transaksi Harian'!$A:$A, "<"&($B9+1), 'Transaksi Harian'!$D:$D, TRIM(E$1)) -> 0 | F9: =SUMIFS('Transaksi Harian'!$J:$J, 'Transaksi Harian'!$A:$A, ">="&$B9, 'Transaksi Harian'!$A:$A, "<"&($B9+1), 'Transaksi Harian'!$D:$D, TRIM(F$1)) -> 0 | G9: =SUMIFS('Transaksi Harian'!$J:$J, 'Transaksi Harian'!$A:$A, ">="&$B9, 'Transaksi Harian'!$A:$A, "<"&($B9+1), 'Transaksi Harian'!$D:$D, TRIM(G$1)) -> 0 | H9: =SUMIFS('Transaksi Harian'!$J:$J, 'Transaksi Harian'!$A:$A, ">="&$B9, 'Transaksi Harian'!$A:$A, "<"&($B9+1)) - SUMIFS('Transaksi Harian'!$H:$H, 'Transaksi Harian'!$A:$A, ">="&$B9, 'Transaksi Harian'!$A:$A, "<"&($B9+1)) -> 0
B10: 46182 | C10: =COUNTIFS('Transaksi Harian'!$A:$A, ">="&$B10, 'Transaksi Harian'!$A:$A, "<"&($B10+1)) -> 0 | D10: =SUMIFS('Transaksi Harian'!$J:$J, 'Transaksi Harian'!$A:$A, ">="&$B10, 'Transaksi Harian'!$A:$A, "<"&($B10+1), 'Transaksi Harian'!$D:$D, TRIM(D$1)) -> 0 | E10: =SUMIFS('Transaksi Harian'!$J:$J, 'Transaksi Harian'!$A:$A, ">="&$B10, 'Transaksi Harian'!$A:$A, "<"&($B10+1), 'Transaksi Harian'!$D:$D, TRIM(E$1)) -> 0 | F10: =SUMIFS('Transaksi Harian'!$J:$J, 'Transaksi Harian'!$A:$A, ">="&$B10, 'Transaksi Harian'!$A:$A, "<"&($B10+1), 'Transaksi Harian'!$D:$D, TRIM(F$1)) -> 0 | G10: =SUMIFS('Transaksi Harian'!$J:$J, 'Transaksi Harian'!$A:$A, ">="&$B10, 'Transaksi Harian'!$A:$A, "<"&($B10+1), 'Transaksi Harian'!$D:$D, TRIM(G$1)) -> 0 | H10: =SUMIFS('Transaksi Harian'!$J:$J, 'Transaksi Harian'!$A:$A, ">="&$B10, 'Transaksi Harian'!$A:$A, "<"&($B10+1)) - SUMIFS('Transaksi Harian'!$H:$H, 'Transaksi Harian'!$A:$A, ">="&$B10, 'Transaksi Harian'!$A:$A, "<"&($B10+1)) -> 0
B11: 46183 | C11: =COUNTIFS('Transaksi Harian'!$A:$A, ">="&$B11, 'Transaksi Harian'!$A:$A, "<"&($B11+1)) -> 0 | D11: =SUMIFS('Transaksi Harian'!$J:$J, 'Transaksi Harian'!$A:$A, ">="&$B11, 'Transaksi Harian'!$A:$A, "<"&($B11+1), 'Transaksi Harian'!$D:$D, TRIM(D$1)) -> 0 | E11: =SUMIFS('Transaksi Harian'!$J:$J, 'Transaksi Harian'!$A:$A, ">="&$B11, 'Transaksi Harian'!$A:$A, "<"&($B11+1), 'Transaksi Harian'!$D:$D, TRIM(E$1)) -> 0 | F11: =SUMIFS('Transaksi Harian'!$J:$J, 'Transaksi Harian'!$A:$A, ">="&$B11, 'Transaksi Harian'!$A:$A, "<"&($B11+1), 'Transaksi Harian'!$D:$D, TRIM(F$1)) -> 0 | G11: =SUMIFS('Transaksi Harian'!$J:$J, 'Transaksi Harian'!$A:$A, ">="&$B11, 'Transaksi Harian'!$A:$A, "<"&($B11+1), 'Transaksi Harian'!$D:$D, TRIM(G$1)) -> 0 | H11: =SUMIFS('Transaksi Harian'!$J:$J, 'Transaksi Harian'!$A:$A, ">="&$B11, 'Transaksi Harian'!$A:$A, "<"&($B11+1)) - SUMIFS('Transaksi Harian'!$H:$H, 'Transaksi Harian'!$A:$A, ">="&$B11, 'Transaksi Harian'!$A:$A, "<"&($B11+1)) -> 0
B12: 46184 | C12: =COUNTIFS('Transaksi Harian'!$A:$A, ">="&$B12, 'Transaksi Harian'!$A:$A, "<"&($B12+1)) -> 0 | D12: =SUMIFS('Transaksi Harian'!$J:$J, 'Transaksi Harian'!$A:$A, ">="&$B12, 'Transaksi Harian'!$A:$A, "<"&($B12+1), 'Transaksi Harian'!$D:$D, TRIM(D$1)) -> 0 | E12: =SUMIFS('Transaksi Harian'!$J:$J, 'Transaksi Harian'!$A:$A, ">="&$B12, 'Transaksi Harian'!$A:$A, "<"&($B12+1), 'Transaksi Harian'!$D:$D, TRIM(E$1)) -> 0 | F12: =SUMIFS('Transaksi Harian'!$J:$J, 'Transaksi Harian'!$A:$A, ">="&$B12, 'Transaksi Harian'!$A:$A, "<"&($B12+1), 'Transaksi Harian'!$D:$D, TRIM(F$1)) -> 0 | G12: =SUMIFS('Transaksi Harian'!$J:$J, 'Transaksi Harian'!$A:$A, ">="&$B12, 'Transaksi Harian'!$A:$A, "<"&($B12+1), 'Transaksi Harian'!$D:$D, TRIM(G$1)) -> 0 | H12: =SUMIFS('Transaksi Harian'!$J:$J, 'Transaksi Harian'!$A:$A, ">="&$B12, 'Transaksi Harian'!$A:$A, "<"&($B12+1)) - SUMIFS('Transaksi Harian'!$H:$H, 'Transaksi Harian'!$A:$A, ">="&$B12, 'Transaksi Harian'!$A:$A, "<"&($B12+1)) -> 0
B13: 46185 | C13: =COUNTIFS('Transaksi Harian'!$A:$A, ">="&$B13, 'Transaksi Harian'!$A:$A, "<"&($B13+1)) -> 0 | D13: =SUMIFS('Transaksi Harian'!$J:$J, 'Transaksi Harian'!$A:$A, ">="&$B13, 'Transaksi Harian'!$A:$A, "<"&($B13+1), 'Transaksi Harian'!$D:$D, TRIM(D$1)) -> 0 | E13: =SUMIFS('Transaksi Harian'!$J:$J, 'Transaksi Harian'!$A:$A, ">="&$B13, 'Transaksi Harian'!$A:$A, "<"&($B13+1), 'Transaksi Harian'!$D:$D, TRIM(E$1)) -> 0 | F13: =SUMIFS('Transaksi Harian'!$J:$J, 'Transaksi Harian'!$A:$A, ">="&$B13, 'Transaksi Harian'!$A:$A, "<"&($B13+1), 'Transaksi Harian'!$D:$D, TRIM(F$1)) -> 0 | G13: =SUMIFS('Transaksi Harian'!$J:$J, 'Transaksi Harian'!$A:$A, ">="&$B13, 'Transaksi Harian'!$A:$A, "<"&($B13+1), 'Transaksi Harian'!$D:$D, TRIM(G$1)) -> 0 | H13: =SUMIFS('Transaksi Harian'!$J:$J, 'Transaksi Harian'!$A:$A, ">="&$B13, 'Transaksi Harian'!$A:$A, "<"&($B13+1)) - SUMIFS('Transaksi Harian'!$H:$H, 'Transaksi Harian'!$A:$A, ">="&$B13, 'Transaksi Harian'!$A:$A, "<"&($B13+1)) -> 0
... B31: 46203 | C31: =COUNTIFS('Transaksi Harian'!$A:$A, ">="&$B31, 'Transaksi Harian'!$A:$A, "<"&($B31+1)) -> 0 | D31: =SUMIFS('Transaksi Harian'!$J:$J, 'Transaksi Harian'!$A:$A, ">="&$B31, 'Transaksi Harian'!$A:$A, "<"&($B31+1), 'Transaksi Harian'!$D:$D, TRIM(D$1)) -> 0 | E31: =SUMIFS('Transaksi Harian'!$J:$J, 'Transaksi Harian'!$A:$A, ">="&$B31, 'Transaksi Harian'!$A:$A, "<"&($B31+1), 'Transaksi Harian'!$D:$D, TRIM(E$1)) -> 0 | F31: =SUMIFS('Transaksi Harian'!$J:$J, 'Transaksi Harian'!$A:$A, ">="&$B31, 'Transaksi Harian'!$A:$A, "<"&($B31+1), 'Transaksi Harian'!$D:$D, TRIM(F$1)) -> 0 | G31: =SUMIFS('Transaksi Harian'!$J:$J, 'Transaksi Harian'!$A:$A, ">="&$B31, 'Transaksi Harian'!$A:$A, "<"&($B31+1), 'Transaksi Harian'!$D:$D, TRIM(G$1)) -> 0 | H31: =SUMIFS('Transaksi Harian'!$J:$J, 'Transaksi Harian'!$A:$A, ">="&$B31, 'Transaksi Harian'!$A:$A, "<"&($B31+1)) - SUMIFS('Transaksi Harian'!$H:$H, 'Transaksi Harian'!$A:$A, ">="&$B31, 'Transaksi Harian'!$A:$A, "<"&($B31+1)) -> 0
C32: =COUNTIFS('Transaksi Harian'!$A:$A, ">="&$B32, 'Transaksi Harian'!$A:$A, "<"&($B32+1)) -> 0 | D32: =SUMIFS('Transaksi Harian'!$J:$J, 'Transaksi Harian'!$A:$A, ">="&$B32, 'Transaksi Harian'!$A:$A, "<"&($B32+1), 'Transaksi Harian'!$D:$D, TRIM(D$1)) -> 0 | E32: =SUMIFS('Transaksi Harian'!$J:$J, 'Transaksi Harian'!$A:$A, ">="&$B32, 'Transaksi Harian'!$A:$A, "<"&($B32+1), 'Transaksi Harian'!$D:$D, TRIM(E$1)) -> 0 | F32: =SUMIFS('Transaksi Harian'!$J:$J, 'Transaksi Harian'!$A:$A, ">="&$B32, 'Transaksi Harian'!$A:$A, "<"&($B32+1), 'Transaksi Harian'!$D:$D, TRIM(F$1)) -> 0 | G32: =SUMIFS('Transaksi Harian'!$J:$J, 'Transaksi Harian'!$A:$A, ">="&$B32, 'Transaksi Harian'!$A:$A, "<"&($B32+1), 'Transaksi Harian'!$D:$D, TRIM(G$1)) -> 0 | H32: =SUMIFS('Transaksi Harian'!$J:$J, 'Transaksi Harian'!$A:$A, ">="&$B32, 'Transaksi Harian'!$A:$A, "<"&($B32+1)) - SUMIFS('Transaksi Harian'!$H:$H, 'Transaksi Harian'!$A:$A, ">="&$B32, 'Transaksi Harian'!$A:$A, "<"&($B32+1)) -> 0
B33: GRAND TOTAL

Sheet Form Responses 1
A1: Timestamp | B1: Pertanyaan Tanpa Judul

Sheet Master_Dropdown
A1: Daftar Barang/Layanan | C1: Kategori Dinamis | D1: Jenis Dinamis | F1: Nama Barang Dinamis | H1: Merk Dinamis
A2: =IFERROR(__xludf.DUMMYFUNCTION("SORT(UNIQUE(FILTER(VSTACK('Stok Digital'!C2:C2451, 'Stok Fisik'!C2:C2451), VSTACK('Stok Digital'!C2:C2451, 'Stok Fisik'!C2:C2451)<>"""")))"),"ACOME ACC Mini Fan AF002 Dark Blue") -> ACOME ACC Mini Fan AF002 Dark Blue | C2: =IFERROR(__xludf.DUMMYFUNCTION("IF('Input Produk Baru'!E3=""Fisik"", SORT(UNIQUE(FILTER('Stok Fisik'!B2:B2451, 'Stok Fisik'!B2:B2451<>""""))), IF('Input Produk Baru'!E3=""Digital"", SORT(UNIQUE(FILTER('Stok Digital'!B2:B2451, 'Stok Digital'!B2:B2451<>""""))), IFERROR(1/0)))"),"AKSESORIS") -> AKSESORIS | D2: =IFERROR(__xludf.DUMMYFUNCTION("IF('Input Produk Baru'!E3=""Fisik"", SORT(UNIQUE(FILTER('Stok Fisik'!E2:E2451, 'Stok Fisik'!E2:E2451<>""""))), IF('Input Produk Baru'!E3=""Digital"", SORT(UNIQUE(FILTER('Stok Digital'!E2:E2451, 'Stok Digital'!E2:E2451<>""""))), IFERROR(1/0)))"),"ADAPTER") -> ADAPTER | F2: =IFERROR(__xludf.DUMMYFUNCTION("IF('Input Produk Baru'!E3=""Fisik"", IFERROR(UNIQUE(FILTER('Stok Fisik'!C2:C2451, 'Stok Fisik'!C2:C2451<>""""))), IF('Input Produk Baru'!E3=""Digital"", IFERROR(UNIQUE(FILTER('Stok Digital'!C2:C2451, 'Stok Digital'!C2:C2451<>""""))), IFERROR(UNIQUE({FILTE"&"R('Stok Fisik'!C2:C2451, 'Stok Fisik'!C2:C2451<>""""); FILTER('Stok Digital'!C2:C2451, 'Stok Digital'!C2:C2451<>"""")}), """")))"),"vivan VSPT04T PRO") -> vivan VSPT04T PRO | H2: {=SORT(UNIQUE({TRIM('Stok Fisik'!D2:D2451); TRIM('Stok Digital'!D2:D2451)}))}
A3: =IFERROR(__xludf.DUMMYFUNCTION("""COMPUTED_VALUE"""),"ACOME ACC Ows Earphone A21 Black (SKU RJA-ACOM-0927)") -> ACOME ACC Ows Earphone A21 Black (SKU RJA-ACOM-0927) | C3: =IFERROR(__xludf.DUMMYFUNCTION("""COMPUTED_VALUE"""),"Aksesoris") -> Aksesoris | D3: =IFERROR(__xludf.DUMMYFUNCTION("""COMPUTED_VALUE"""),"AKSESORIS LAIN") -> AKSESORIS LAIN | F3: =IFERROR(__xludf.DUMMYFUNCTION("""COMPUTED_VALUE"""),"ACOME Microphone AWA-V7B Black") -> ACOME Microphone AWA-V7B Black | H3: ACOME
A4: =IFERROR(__xludf.DUMMYFUNCTION("""COMPUTED_VALUE"""),"ACOME ACC Ows Earphone A21 Black (SKU RJA-ACOM-0944)") -> ACOME ACC Ows Earphone A21 Black (SKU RJA-ACOM-0944) | C4: =IFERROR(__xludf.DUMMYFUNCTION("""COMPUTED_VALUE"""),"LAIN LAIN") -> LAIN LAIN | D4: =IFERROR(__xludf.DUMMYFUNCTION("""COMPUTED_VALUE"""),"Aksesoris Lainnya") -> Aksesoris Lainnya | F4: =IFERROR(__xludf.DUMMYFUNCTION("""COMPUTED_VALUE"""),"ACOME ACC Mini Fan AF002 Dark Blue") -> ACOME ACC Mini Fan AF002 Dark Blue | H4: AIBIMY
A5: =IFERROR(__xludf.DUMMYFUNCTION("""COMPUTED_VALUE"""),"ACOME Microphone AWA-V7B Black") -> ACOME Microphone AWA-V7B Black | C5: =IFERROR(__xludf.DUMMYFUNCTION("""COMPUTED_VALUE"""),"PULSA") -> PULSA | D5: =IFERROR(__xludf.DUMMYFUNCTION("""COMPUTED_VALUE"""),"AUX") -> AUX | F5: =IFERROR(__xludf.DUMMYFUNCTION("""COMPUTED_VALUE"""),"ACOME TF CARD 32G TF WITH Package colourful") -> ACOME TF CARD 32G TF WITH Package colourful | H5: AIMILO
A6: =IFERROR(__xludf.DUMMYFUNCTION("""COMPUTED_VALUE"""),"ACOME OWS bluetooth earphone OpenSoft AE02") -> ACOME OWS bluetooth earphone OpenSoft AE02 | D6: =IFERROR(__xludf.DUMMYFUNCTION("""COMPUTED_VALUE"""),"AUX AV-003 1,5 M") -> AUX AV-003 1,5 M | F6: =IFERROR(__xludf.DUMMYFUNCTION("""COMPUTED_VALUE"""),"ACOME selfie stick SS07A black (SKU RJA-ACOM-0890)") -> ACOME selfie stick SS07A black (SKU RJA-ACOM-0890) | H6: ALIENS
A7: =IFERROR(__xludf.DUMMYFUNCTION("""COMPUTED_VALUE"""),"ACOME selfie stick SS07A black (SKU RJA-ACOM-0890)") -> ACOME selfie stick SS07A black (SKU RJA-ACOM-0890) | D7: =IFERROR(__xludf.DUMMYFUNCTION("""COMPUTED_VALUE"""),"BANDO") -> BANDO | F7: =IFERROR(__xludf.DUMMYFUNCTION("""COMPUTED_VALUE"""),"ACOME selfie stick SS07A black (SKU RJA-ACOM-0903)") -> ACOME selfie stick SS07A black (SKU RJA-ACOM-0903) | H7: AXIS
A8: =IFERROR(__xludf.DUMMYFUNCTION("""COMPUTED_VALUE"""),"ACOME selfie stick SS07A black (SKU RJA-ACOM-0903)") -> ACOME selfie stick SS07A black (SKU RJA-ACOM-0903) | D8: =IFERROR(__xludf.DUMMYFUNCTION("""COMPUTED_VALUE"""),"BATERAI") -> BATERAI | F8: =IFERROR(__xludf.DUMMYFUNCTION("""COMPUTED_VALUE"""),"ACOME ACC Ows Earphone A21 Black (SKU RJA-ACOM-0927)") -> ACOME ACC Ows Earphone A21 Black (SKU RJA-ACOM-0927) | H8: BASEUSE
A9: =IFERROR(__xludf.DUMMYFUNCTION("""COMPUTED_VALUE"""),"ACOME TF CARD 32G TF WITH Package colourful") -> ACOME TF CARD 32G TF WITH Package colourful | D9: =IFERROR(__xludf.DUMMYFUNCTION("""COMPUTED_VALUE"""),"BATOK CHARGER") -> BATOK CHARGER | F9: =IFERROR(__xludf.DUMMYFUNCTION("""COMPUTED_VALUE"""),"ACOME Tws Earphone Inpods AT03 Black (SKU RJA-ACOM-0928)") -> ACOME Tws Earphone Inpods AT03 Black (SKU RJA-ACOM-0928) | H9: DAP
A10: =IFERROR(__xludf.DUMMYFUNCTION("""COMPUTED_VALUE"""),"ACOME Tws Earphone Inpods AT03 Black (SKU RJA-ACOM-0928)") -> ACOME Tws Earphone Inpods AT03 Black (SKU RJA-ACOM-0928) | D10: =IFERROR(__xludf.DUMMYFUNCTION("""COMPUTED_VALUE"""),"BROADCAST") -> BROADCAST | F10: =IFERROR(__xludf.DUMMYFUNCTION("""COMPUTED_VALUE"""),"ACOME TWS Inpods AT09 Black (SKU RJA-ACOM-0931)") -> ACOME TWS Inpods AT09 Black (SKU RJA-ACOM-0931) | H10: DATA
A11: =IFERROR(__xludf.DUMMYFUNCTION("""COMPUTED_VALUE"""),"ACOME Tws Earphone Inpods AT03 Black (SKU RJA-ACOM-0932)") -> ACOME Tws Earphone Inpods AT03 Black (SKU RJA-ACOM-0932) | D11: =IFERROR(__xludf.DUMMYFUNCTION("""COMPUTED_VALUE"""),"CAR CHARGER") -> CAR CHARGER | F11: =IFERROR(__xludf.DUMMYFUNCTION("""COMPUTED_VALUE"""),"ACOME Tws Earphone Inpods AT03 Black (SKU RJA-ACOM-0932)") -> ACOME Tws Earphone Inpods AT03 Black (SKU RJA-ACOM-0932) | H11: FLECO
A12: =IFERROR(__xludf.DUMMYFUNCTION("""COMPUTED_VALUE"""),"ACOME Tws Earphone Inpods AT03 Green") -> ACOME Tws Earphone Inpods AT03 Green | D12: =IFERROR(__xludf.DUMMYFUNCTION("""COMPUTED_VALUE"""),"CARD READER") -> CARD READER | F12: =IFERROR(__xludf.DUMMYFUNCTION("""COMPUTED_VALUE"""),"ACOME TWS Inpods AT09 Black (SKU RJA-ACOM-0941)") -> ACOME TWS Inpods AT09 Black (SKU RJA-ACOM-0941) | H12: GAMEN
A13: =IFERROR(__xludf.DUMMYFUNCTION("""COMPUTED_VALUE"""),"ACOME TWS Inpods AT09 Black (SKU RJA-ACOM-0931)") -> ACOME TWS Inpods AT09 Black (SKU RJA-ACOM-0931) | D13: =IFERROR(__xludf.DUMMYFUNCTION("""COMPUTED_VALUE"""),"CHARGER AKI") -> CHARGER AKI | F13: =IFERROR(__xludf.DUMMYFUNCTION("""COMPUTED_VALUE"""),"ACOME Tws Earphone Inpods AT03 Green") -> ACOME Tws Earphone Inpods AT03 Green | H13: GAN
A14: =IFERROR(__xludf.DUMMYFUNCTION("""COMPUTED_VALUE"""),"ACOME TWS Inpods AT09 Black (SKU RJA-ACOM-0941)") -> ACOME TWS Inpods AT09 Black (SKU RJA-ACOM-0941) | D14: =IFERROR(__xludf.DUMMYFUNCTION("""COMPUTED_VALUE"""),"CONVERTER") -> CONVERTER | F14: =IFERROR(__xludf.DUMMYFUNCTION("""COMPUTED_VALUE"""),"ACOME OWS bluetooth earphone OpenSoft AE02") -> ACOME OWS bluetooth earphone OpenSoft AE02 | H14: HDMI
A15: =IFERROR(__xludf.DUMMYFUNCTION("""COMPUTED_VALUE"""),"ADAPTER 7IN1 TYPE C+ USB A GREY") -> ADAPTER 7IN1 TYPE C+ USB A GREY | D15: =IFERROR(__xludf.DUMMYFUNCTION("""COMPUTED_VALUE"""),"COOLING PAD") -> COOLING PAD | F15: =IFERROR(__xludf.DUMMYFUNCTION("""COMPUTED_VALUE"""),"ACOME ACC Ows Earphone A21 Black (SKU RJA-ACOM-0944)") -> ACOME ACC Ows Earphone A21 Black (SKU RJA-ACOM-0944) | H15: HT
A16: =IFERROR(__xludf.DUMMYFUNCTION("""COMPUTED_VALUE"""),"ANTENA AUX") -> ANTENA AUX | D16: =IFERROR(__xludf.DUMMYFUNCTION("""COMPUTED_VALUE"""),"DOGLE") -> DOGLE | F16: =IFERROR(__xludf.DUMMYFUNCTION("""COMPUTED_VALUE"""),"ADAPTER 7IN1 TYPE C+ USB A GREY") -> ADAPTER 7IN1 TYPE C+ USB A GREY | H16: INDOSAT
A17: =IFERROR(__xludf.DUMMYFUNCTION("""COMPUTED_VALUE"""),"ARC BBQ LIGHTER") -> ARC BBQ LIGHTER | D17: =IFERROR(__xludf.DUMMYFUNCTION("""COMPUTED_VALUE"""),"DONGGLE") -> DONGGLE | F17: =IFERROR(__xludf.DUMMYFUNCTION("""COMPUTED_VALUE"""),"MOUSEPAD GAMER") -> MOUSEPAD GAMER | H17: INFINIX
A18: =IFERROR(__xludf.DUMMYFUNCTION("""COMPUTED_VALUE"""),"AUX 2 IN 1 1 M") -> AUX 2 IN 1 1 M | D18: =IFERROR(__xludf.DUMMYFUNCTION("""COMPUTED_VALUE"""),"FAN") -> FAN | F18: =IFERROR(__xludf.DUMMYFUNCTION("""COMPUTED_VALUE"""),"ANTENA AUX") -> ANTENA AUX | H18: IPHONE
A19: =IFERROR(__xludf.DUMMYFUNCTION("""COMPUTED_VALUE"""),"AUX 2 IN 1 1,5 M") -> AUX 2 IN 1 1,5 M | D19: =IFERROR(__xludf.DUMMYFUNCTION("""COMPUTED_VALUE"""),"FLASHDISK") -> FLASHDISK | F19: =IFERROR(__xludf.DUMMYFUNCTION("""COMPUTED_VALUE"""),"ARC BBQ LIGHTER") -> ARC BBQ LIGHTER | H19: Iphone
A20: =IFERROR(__xludf.DUMMYFUNCTION("""COMPUTED_VALUE"""),"AUX ACCESORIES") -> AUX ACCESORIES | D20: =IFERROR(__xludf.DUMMYFUNCTION("""COMPUTED_VALUE"""),"GURITA") -> GURITA | F20: =IFERROR(__xludf.DUMMYFUNCTION("""COMPUTED_VALUE"""),"AUX 2 IN 1 1,5 M") -> AUX 2 IN 1 1,5 M | H20: J
A21: =IFERROR(__xludf.DUMMYFUNCTION("""COMPUTED_VALUE"""),"AUX ALIEN") -> AUX ALIEN | D21: =IFERROR(__xludf.DUMMYFUNCTION("""COMPUTED_VALUE"""),"HANDFREE") -> HANDFREE | F21: =IFERROR(__xludf.DUMMYFUNCTION("""COMPUTED_VALUE"""),"AUX 2 IN 1 1 M") -> AUX 2 IN 1 1 M | H21: JASPAN
A22: =IFERROR(__xludf.DUMMYFUNCTION("""COMPUTED_VALUE"""),"AUX AV-003 (SKU RJA-AUXA-0066)") -> AUX AV-003 (SKU RJA-AUXA-0066) | D22: =IFERROR(__xludf.DUMMYFUNCTION("""COMPUTED_VALUE"""),"HDMI") -> HDMI | F22: =IFERROR(__xludf.DUMMYFUNCTION("""COMPUTED_VALUE"""),"AUX ACCESORIES") -> AUX ACCESORIES | H22: JOYSEUS
A23: =IFERROR(__xludf.DUMMYFUNCTION("""COMPUTED_VALUE"""),"AUX AV-003 (SKU RJA-AUXA-0067)") -> AUX AV-003 (SKU RJA-AUXA-0067) | D23: =IFERROR(__xludf.DUMMYFUNCTION("""COMPUTED_VALUE"""),"HEADPHONE") -> HEADPHONE | F23: =IFERROR(__xludf.DUMMYFUNCTION("""COMPUTED_VALUE"""),"AUX AV-005 1,5") -> AUX AV-005 1,5 | H23: LANEX
A24: =IFERROR(__xludf.DUMMYFUNCTION("""COMPUTED_VALUE"""),"AUX AV-005 1,5") -> AUX AV-005 1,5 | D24: =IFERROR(__xludf.DUMMYFUNCTION("""COMPUTED_VALUE"""),"HEADSET") -> HEADSET | F24: =IFERROR(__xludf.DUMMYFUNCTION("""COMPUTED_VALUE"""),"AUX ALIEN") -> AUX ALIEN | H24: LAQUE
A25: =IFERROR(__xludf.DUMMYFUNCTION("""COMPUTED_VALUE"""),"AUX CABLE LENYES LIGHTNING TO 3.5MM") -> AUX CABLE LENYES LIGHTNING TO 3.5MM | D25: =IFERROR(__xludf.DUMMYFUNCTION("""COMPUTED_VALUE"""),"HOLDER") -> HOLDER | F25: =IFERROR(__xludf.DUMMYFUNCTION("""COMPUTED_VALUE"""),"AUX AV-003 (SKU RJA-AUXA-0066)") -> AUX AV-003 (SKU RJA-AUXA-0066) | H25: LENYES
